# -*- coding: utf-8 -*-

from odoo import models, fields, api
from odoo.exceptions import UserError, ValidationError

class Mission(models.Model):
   _name='space.mission'
   _description='Space Missions'

   name = fields.Char(
      string='Mission Name',
      required=True
   )
   description = fields.Text(
      string='Description'
   )
   fuel_required = fields.Integer(
      string='Fuel Required'
   )
   ship_id = fields.Many2one(
      comodel_name='space.ship',
      string='Mission Space Ship',
   )
   captain_id = fields.Many2one(
      comodel_name='res.partner',
      string='Crew Captain'
   )
   crew_ids = fields.Many2many(
      comodel_name='res.partner',
      string='Crew Members'
   )

   # @api.onchange('fuel_required')
   # def filter_ships_by_min_fuel(self):
   #    return self.fuel_required
   @api.onchange('fuel_required')
   def filter_ships_by_fuel_cap(self):
      for rec in self:
         return {
            'domain': {
               'fuel_capacity': [
                  ('fuel_required', '>=', rec.fuel_required)
               ]
            }
         }